# Exception Propagation in Java

Exception propagation is a fundamental concept in Java's exception handling mechanism. It describes the process by which an unhandled exception moves up the call stack, from the method where it originated to its calling methods, until it is either caught by a `try-catch` block or reaches the top of the call stack (the `main` method or the thread's `run` method), at which point the program typically terminates.

## How it Works (The Mechanism)

Imagine a series of method calls: `Method A` calls `Method B`, and `Method B` calls `Method C`. This forms a call stack:

```
main()
  -> MethodA()
     -> MethodB()
        -> MethodC()
```

1.  **Exception Origin:** If an exception occurs within `MethodC` (e.g., `MethodC` tries to divide by zero), and `MethodC` does not contain a `try-catch` block to handle that specific exception.
2.  **Propagation Upwards:** The Java Virtual Machine (JVM) will "propagate" or "throw" this unhandled exception back to the method that called `MethodC`, which is `MethodB`.
3.  **Search for a Handler:** The JVM then checks `MethodB`. Does `MethodB` have a `try-catch` block that can handle this exception?
    *   If **yes**, the exception is caught and handled by `MethodB`'s `catch` block. The propagation stops, and the program continues execution from after the `catch` block in `MethodB`.
    *   If **no**, the exception is further propagated up the stack to `MethodA`, the method that called `MethodB`.
4.  **Continued Propagation:** This process repeats. The JVM checks `MethodA` for a suitable `try-catch` block.
    *   If **yes**, `MethodA` handles it, and execution continues.
    *   If **no**, the exception is propagated to `main()` (or whatever called `MethodA`).
5.  **JVM as Last Resort:** If the exception reaches the `main()` method and `main()` also does not handle it, the JVM will catch the exception, print its stack trace to the console (standard error stream), and terminate the program.

This "unwinding" of the call stack until a handler is found (or the stack is exhausted) is the essence of exception propagation.

## Key Principles

*   **Call Stack Unwinding:** When an exception is thrown, the JVM unwinds the call stack, popping method frames off the stack one by one, looking for a handler.
*   **Search for a Handler:** The search for an appropriate `catch` block begins in the method where the exception occurred and moves upwards through the call hierarchy.
*   **JVM as the Last Handler:** If no method in the call stack handles the exception, the JVM itself acts as the ultimate exception handler, terminating the program and usually printing a stack trace.
*   **Checked vs. Unchecked Exceptions:**
    *   **Unchecked Exceptions (Runtime Exceptions and their subclasses):** These exceptions do not *need* to be declared using `throws` or caught explicitly. They propagate automatically up the call stack if not handled.
    *   **Checked Exceptions:** These exceptions *must* either be caught by a `try-catch` block or declared in the method signature using the `throws` keyword. If a method might throw a checked exception, and doesn't handle it, it *must* declare that it `throws` that exception. This forces the calling method to either handle or re-declare it, thus explicitly showing the potential propagation.

---

## Examples

Let's illustrate exception propagation with a few scenarios.

### Scenario 1: Unhandled Unchecked Exception Propagation

In this example, `method3` throws an `ArithmeticException` (an unchecked exception). Neither `method3`, `method2`, nor `method1` handles it. It propagates all the way up to `main`, which also doesn't handle it, leading to program termination.

**`UnhandledUncheckedPropagation.java`**

```java
public class UnhandledUncheckedPropagation {

    public static void method3() {
        System.out.println("Inside method3");
        // This will cause an ArithmeticException (divide by zero)
        int result = 10 / 0; 
        System.out.println("Result in method3: " + result); // This line will not be reached
    }

    public static void method2() {
        System.out.println("Inside method2, calling method3...");
        method3();
        System.out.println("Back in method2."); // This line will not be reached if method3 throws exception
    }

    public static void method1() {
        System.out.println("Inside method1, calling method2...");
        method2();
        System.out.println("Back in method1."); // This line will not be reached if method2 propagates exception
    }

    public static void main(String[] args) {
        System.out.println("Starting program (main method).");
        method1();
        System.out.println("Program finished (main method)."); // This line will not be reached
    }
}
```

**Input:**
Run the `UnhandledUncheckedPropagation` class.

**Output:**

```
Starting program (main method).
Inside method1, calling method2...
Inside method2, calling method3...
Exception in thread "main" java.lang.ArithmeticException: / by zero
	at UnhandledUncheckedPropagation.method3(UnhandledUncheckedPropagation.java:8)
	at UnhandledUncheckedPropagation.method2(UnhandledUncheckedPropagation.java:15)
	at UnhandledUncheckedPropagation.method1(UnhandledUncheckedPropagation.java:21)
	at UnhandledUncheckedPropagation.main(UnhandledUncheckedPropagation.java:27)
```

**Explanation:**
1.  `main` calls `method1`.
2.  `method1` calls `method2`.
3.  `method2` calls `method3`.
4.  `method3` executes `10 / 0`, which throws an `ArithmeticException`.
5.  `method3` has no `try-catch`, so the exception propagates to `method2`.
6.  `method2` has no `try-catch`, so the exception propagates to `method1`.
7.  `method1` has no `try-catch`, so the exception propagates to `main`.
8.  `main` has no `try-catch`, so the JVM catches the exception, prints the stack trace, and terminates the program. Notice that the `System.out.println` statements after the problematic calls are never reached.

### Scenario 2: Unhandled Checked Exception Propagation

In this scenario, `method3` throws an `IOException` (a checked exception). Because it's a checked exception, each method in the call stack that doesn't handle it *must* declare that it `throws` the exception.

**`UnhandledCheckedPropagation.java`**

```java
import java.io.IOException;

public class UnhandledCheckedPropagation {

    // method3 declares that it might throw an IOException
    public static void method3() throws IOException {
        System.out.println("Inside method3");
        // Simulate an IO operation that might fail
        boolean fileOperationFailed = true; 
        if (fileOperationFailed) {
            throw new IOException("Simulated file operation failed in method3!");
        }
        System.out.println("File operation successful in method3."); // Not reached
    }

    // method2 calls method3, and since method3 throws IOException and method2 doesn't catch it,
    // method2 MUST declare that it throws IOException as well.
    public static void method2() throws IOException {
        System.out.println("Inside method2, calling method3...");
        method3();
        System.out.println("Back in method2."); // Not reached if method3 throws
    }

    // method1 calls method2, and since method2 throws IOException and method1 doesn't catch it,
    // method1 MUST declare that it throws IOException as well.
    public static void method1() throws IOException {
        System.out.println("Inside method1, calling method2...");
        method2();
        System.out.println("Back in method1."); // Not reached if method2 propagates
    }

    public static void main(String[] args) {
        System.out.println("Starting program (main method).");
        try {
            // main calls method1. Since method1 throws IOException, main must either catch it
            // or declare that it throws IOException (which would then be caught by JVM).
            // For this example, we're letting it propagate to show termination.
            method1();
        } catch (IOException e) {
            // This catch block demonstrates where it could be handled,
            // but for this "unhandled" scenario, imagine this block wasn't here.
            // For the output below, this try-catch is around main's call to method1.
            System.err.println("Caught an IOException in main: " + e.getMessage());
            e.printStackTrace();
        }
        System.out.println("Program finished (main method)."); // Reached if caught, not reached if truly unhandled
    }
}
```

**Note:** If the `try-catch` block around `method1()` call in `main()` was removed, the `main` method would also need `throws IOException` in its signature, and then the JVM would catch it and terminate. The current setup demonstrates *where* it would be caught if handled.

**Input:**
Run the `UnhandledCheckedPropagation` class.

**Output (with `try-catch` in `main` as shown in code):**

```
Starting program (main method).
Inside method1, calling method2...
Inside method2, calling method3...
Caught an IOException in main: Simulated file operation failed in method3!
java.io.IOException: Simulated file operation failed in method3!
	at UnhandledCheckedPropagation.method3(UnhandledCheckedPropagation.java:13)
	at UnhandledCheckedPropagation.method2(UnhandledCheckedPropagation.java:22)
	at UnhandledCheckedPropagation.method1(UnhandledCheckedPropagation.java:30)
	at UnhandledCheckedPropagation.main(UnhandledCheckedPropagation.java:38)
Program finished (main method).
```

**Explanation:**
1.  `method3` throws `IOException`. Because it's checked, `method3`'s signature *must* include `throws IOException`.
2.  `method2` calls `method3`. Since `method2` doesn't handle `IOException` itself, its signature *must* also include `throws IOException`.
3.  `method1` calls `method2`. Since `method1` doesn't handle `IOException` itself, its signature *must* also include `throws IOException`.
4.  `main` calls `method1`. `main` chooses to *catch* the `IOException`.
5.  When the `IOException` is thrown in `method3`, it propagates up: `method3` -> `method2` -> `method1`.
6.  When it reaches `main`, the `try-catch` block in `main` catches it.
7.  The program prints the error message and stack trace from the `catch` block, and then continues execution after the `catch` block (printing "Program finished"). The program does *not* terminate abruptly because the exception was handled.

If the `try-catch` in `main` was removed and `main` was changed to `public static void main(String[] args) throws IOException`, the output would be similar to Scenario 1, but with `IOException` and the program would terminate.

### Scenario 3: Handling an Exception During Propagation

This example shows how propagation stops once an appropriate `try-catch` block is found. `method3` throws a `RuntimeException`, but `method2` catches it.

**`HandledPropagation.java`**

```java
public class HandledPropagation {

    public static void method3() {
        System.out.println("Inside method3");
        // Throw a NullPointerException (unchecked exception)
        throw new NullPointerException("NPE originated in method3!"); 
    }

    public static void method2() {
        System.out.println("Inside method2, calling method3...");
        try {
            method3(); // This call might throw an exception
            System.out.println("This line in method2 will not be reached if method3 throws.");
        } catch (NullPointerException e) {
            System.out.println("Caught NullPointerException in method2: " + e.getMessage());
            System.out.println("Recovering from exception in method2...");
        }
        System.out.println("Execution continues in method2 after potential exception.");
    }

    public static void method1() {
        System.out.println("Inside method1, calling method2...");
        method2();
        System.out.println("Back in method1.");
    }

    public static void main(String[] args) {
        System.out.println("Starting program (main method).");
        method1();
        System.out.println("Program finished (main method).");
    }
}
```

**Input:**
Run the `HandledPropagation` class.

**Output:**

```
Starting program (main method).
Inside method1, calling method2...
Inside method2, calling method3...
Caught NullPointerException in method2: NPE originated in method3!
Recovering from exception in method2...
Execution continues in method2 after potential exception.
Back in method1.
Program finished (main method).
```

**Explanation:**
1.  `main` calls `method1`.
2.  `method1` calls `method2`.
3.  `method2` enters its `try` block and calls `method3`.
4.  `method3` throws a `NullPointerException`.
5.  `method3` has no handler, so the exception propagates to its caller, `method2`.
6.  `method2` has a `try-catch` block that specifically catches `NullPointerException`.
7.  The exception is caught by `method2`. The code inside `method2`'s `catch` block executes.
8.  After the `catch` block finishes, the execution continues normally from where the `try-catch` block ends in `method2`.
9.  `method2` completes its execution and returns control to `method1`.
10. `method1` completes and returns control to `main`.
11. `main` completes, and the program terminates normally. Notice there's no program crash or full stack trace printed by the JVM because the exception was handled gracefully.

---

## Important Considerations

*   **When to Handle vs. Propagate:**
    *   **Handle:** If a method can fully recover from an exception or perform a meaningful alternative action, it should catch the exception.
    *   **Propagate:** If a method cannot meaningfully handle an exception, it should let it propagate. For checked exceptions, this means declaring `throws` in the method signature. This pushes the responsibility up the call stack to a higher level that might have more context or resources to handle the error (e.g., logging, user notification, graceful shutdown).
*   **Performance:** Exception propagation, especially if exceptions are thrown and caught frequently, can have a performance overhead due to the stack unwinding and object creation. However, for genuinely exceptional conditions, this overhead is usually negligible compared to the cost of the operation itself or the benefit of robust error handling.
*   **Specific Catch Blocks:** Always try to catch specific exception types rather than the general `Exception` class (`catch (Exception e)`). This makes your code more readable, prevents unintended catching of other exceptions, and allows for more precise recovery strategies.

Exception propagation is a powerful mechanism that allows for a clear separation of concerns: methods at a lower level of abstraction can report errors (throw exceptions) without necessarily knowing how to recover from them, leaving the recovery logic to higher-level methods that have a broader context.