A **nested try block** in Java refers to placing one `try-catch-finally` block inside another `try` block. This allows for more granular exception handling, where exceptions occurring in a specific sub-operation can be handled locally, while a broader outer `try` block can handle exceptions related to the overall operation or those not caught by the inner block.

## Why Use Nested Try Blocks?

1.  **Granular Exception Handling:** You can handle specific exceptions that occur within a sub-operation independently, without aborting the entire process.
2.  **Resource Management:** Useful when dealing with multiple resources where the failure of one resource operation might not necessarily require the immediate termination of the parent operation, but you still want to ensure proper cleanup for the failed inner operation. (However, `try-with-resources` is often a cleaner alternative for this specific use case).
3.  **Different Exception Types at Different Levels:** An inner operation might throw a very specific exception, while the outer operation might catch a more general exception or exceptions related to its own setup or context.
4.  **Error Recovery:** Allows you to attempt recovery or alternative actions for specific internal failures, while allowing unhandled internal exceptions to propagate to the outer block for a different recovery strategy or logging.

## How Nested Try Blocks Work (Exception Flow)

1.  **Execution:** Code inside the inner `try` block executes first.
2.  **Inner Exception:** If an exception occurs within the inner `try` block:
    *   The JVM first looks for a matching `catch` block *within the inner `try-catch` structure*.
    *   If a match is found, that inner `catch` block is executed.
    *   After the inner `catch` (and if present, the inner `finally`), execution continues *after the inner `try-catch` block* but *within the outer `try` block*.
3.  **Propagation to Outer Try:** If no matching `catch` block is found for the exception within the inner `try-catch` structure, or if the exception occurs *after* the inner `try-catch` but still within the outer `try` block:
    *   The exception propagates *up* to the outer `try` block.
    *   The JVM then looks for a matching `catch` block within the outer `try-catch` structure.
4.  **Outer Exception:** If an exception occurs directly within the outer `try` block (i.e., outside the inner `try` block), it is handled by the outer `catch` blocks.
5.  **`finally` Blocks:**
    *   Each `try` block can have its own `finally` block.
    *   An inner `finally` block will always execute before its outer `finally` block, regardless of whether an exception occurred or was caught.

## Syntax

```java
try {
    // Outer try block code
    System.out.println("Outer try block starts.");

    try {
        // Inner try block code
        System.out.println("Inner try block starts.");
        // Code that might throw an exception (e.g., division by zero, null pointer)
        System.out.println("Inner try block ends.");
    } catch (InnerExceptionType1 e) {
        // Handle specific exception from inner try
        System.out.println("Inner catch block (InnerExceptionType1): " + e.getMessage());
    } catch (InnerExceptionType2 e) {
        // Handle another specific exception from inner try
        System.out.println("Inner catch block (InnerExceptionType2): " + e.getMessage());
    } finally {
        // Inner finally block (always executes after inner try/catch)
        System.out.println("Inner finally block.");
    }

    // Code in outer try block after inner try-catch
    System.out.println("Outer try block continues after inner block.");

} catch (OuterExceptionType1 e) {
    // Handle specific exception from outer try or propagated from inner
    System.out.println("Outer catch block (OuterExceptionType1): " + e.getMessage());
} catch (Exception e) { // General catch for any unhandled exceptions
    System.out.println("Outer general catch block: " + e.getMessage());
} finally {
    // Outer finally block (always executes after outer try/catch)
    System.out.println("Outer finally block.");
}
```

---

## Example 1: Basic Numeric Operations

This example demonstrates how exceptions are caught at different levels and how `finally` blocks execute.

```java
import java.util.InputMismatchException;
import java.util.Scanner;

public class NestedTryBasicExample {

    public static void main(String[] args) {
        Scanner scanner = new Scanner(System.in);

        try { // Outer try block
            System.out.println("\n--- Outer Try Block ---");
            System.out.print("Enter a numerator for outer division: ");
            int outerNumerator = scanner.nextInt();

            System.out.print("Enter a divisor for outer division: ");
            int outerDivisor = scanner.nextInt();

            try { // Inner try block
                System.out.println("\n--- Inner Try Block ---");
                System.out.print("Enter a string that can be converted to an integer: ");
                String numString = scanner.next();
                int innerNumber = Integer.parseInt(numString); // Might throw NumberFormatException

                System.out.print("Enter a divisor for inner division: ");
                int innerDivisor = scanner.nextInt();

                int innerResult = innerNumber / innerDivisor; // Might throw ArithmeticException
                System.out.println("Inner division result: " + innerResult);
                System.out.println("Inner try block finished successfully.");

            } catch (NumberFormatException e) {
                System.err.println("Inner Catch (NumberFormatException): Invalid number format for inner operation! " + e.getMessage());
            } catch (ArithmeticException e) {
                System.err.println("Inner Catch (ArithmeticException): Cannot divide by zero in inner operation! " + e.getMessage());
            } finally {
                System.out.println("Inner finally block executed.");
            }

            int outerResult = outerNumerator / outerDivisor; // Might throw ArithmeticException
            System.out.println("Outer division result: " + outerResult);
            System.out.println("Outer try block finished successfully.");

        } catch (InputMismatchException e) {
            System.err.println("Outer Catch (InputMismatchException): Invalid input type! Please enter integers. " + e.getMessage());
            scanner.next(); // Consume the invalid input to prevent infinite loop
        } catch (ArithmeticException e) {
            System.err.println("Outer Catch (ArithmeticException): Cannot divide by zero in outer operation! " + e.getMessage());
        } catch (Exception e) { // General catch for any other unexpected exceptions
            System.err.println("Outer Catch (General Exception): An unexpected error occurred! " + e.getMessage());
        } finally {
            System.out.println("Outer finally block executed.");
            scanner.close();
            System.out.println("Scanner closed.");
        }

        System.out.println("\nProgram finished execution.");
    }
}
```

### Input and Output Examples:

**Scenario 1: All operations successful**

*   **Input:**
    ```
    Enter a numerator for outer division: 10
    Enter a divisor for outer division: 2
    Enter a string that can be converted to an integer: 20
    Enter a divisor for inner division: 4
    ```
*   **Output:**
    ```
    --- Outer Try Block ---
    Enter a numerator for outer division: 10
    Enter a divisor for outer division: 2

    --- Inner Try Block ---
    Enter a string that can be converted to an integer: 20
    Enter a divisor for inner division: 4
    Inner division result: 5
    Inner try block finished successfully.
    Inner finally block executed.
    Outer division result: 5
    Outer try block finished successfully.
    Outer finally block executed.
    Scanner closed.

    Program finished execution.
    ```

**Scenario 2: Inner `NumberFormatException`**

*   **Input:**
    ```
    Enter a numerator for outer division: 10
    Enter a divisor for outer division: 2
    Enter a string that can be converted to an integer: abc
    ```
*   **Output:**
    ```
    --- Outer Try Block ---
    Enter a numerator for outer division: 10
    Enter a divisor for outer division: 2

    --- Inner Try Block ---
    Enter a string that can be converted to an integer: abc
    Inner Catch (NumberFormatException): Invalid number format for inner operation! For input string: "abc"
    Inner finally block executed.
    Outer division result: 5
    Outer try block finished successfully.
    Outer finally block executed.
    Scanner closed.

    Program finished execution.
    ```
    *Explanation:* The `NumberFormatException` in the inner `try` is caught by the inner `catch`. The inner `finally` executes. Then, the outer `try` continues and completes successfully.

**Scenario 3: Inner `ArithmeticException`**

*   **Input:**
    ```
    Enter a numerator for outer division: 10
    Enter a divisor for outer division: 2
    Enter a string that can be converted to an integer: 20
    Enter a divisor for inner division: 0
    ```
*   **Output:**
    ```
    --- Outer Try Block ---
    Enter a numerator for outer division: 10
    Enter a divisor for outer division: 2

    --- Inner Try Block ---
    Enter a string that can be converted to an integer: 20
    Enter a divisor for inner division: 0
    Inner Catch (ArithmeticException): Cannot divide by zero in inner operation! / by zero
    Inner finally block executed.
    Outer division result: 5
    Outer try block finished successfully.
    Outer finally block executed.
    Scanner closed.

    Program finished execution.
    ```
    *Explanation:* The `ArithmeticException` in the inner `try` is caught by the inner `catch`. The inner `finally` executes. Then, the outer `try` continues and completes successfully.

**Scenario 4: Outer `ArithmeticException` (propagated from inner)**

*   **Input:**
    ```
    Enter a numerator for outer division: 10
    Enter a divisor for outer division: 0
    ```
*   **Output:**
    ```
    --- Outer Try Block ---
    Enter a numerator for outer division: 10
    Enter a divisor for outer division: 0
    Outer Catch (ArithmeticException): Cannot divide by zero in outer operation! / by zero
    Outer finally block executed.
    Scanner closed.

    Program finished execution.
    ```
    *Explanation:* If the outer divisor is 0, the program doesn't even enter the inner `try` block's execution path for the arithmetic operation. The outer `ArithmeticException` is caught by the outer `catch`.

**Scenario 5: `InputMismatchException` (Outer Catch)**

*   **Input:**
    ```
    Enter a numerator for outer division: ten
    ```
*   **Output:**
    ```
    --- Outer Try Block ---
    Enter a numerator for outer division: ten
    Outer Catch (InputMismatchException): Invalid input type! Please enter integers. null
    Outer finally block executed.
    Scanner closed.

    Program finished execution.
    ```
    *Explanation:* When `scanner.nextInt()` tries to read "ten", it throws an `InputMismatchException`, which is handled by the outer `catch` block.

---

## Example 2: File Operations (Simulated with Nested Try)

This example shows how nested try blocks *could* be used for file operations, though `try-with-resources` is generally preferred for this specific use case (see Example 3).

```java
import java.io.FileWriter;
import java.io.IOException;
import java.io.BufferedWriter;
import java.util.Scanner;

public class NestedTryFileExample {

    public static void main(String[] args) {
        Scanner scanner = new Scanner(System.in);
        FileWriter fileWriter = null; // Declare outside try for outer finally

        System.out.print("Enter filename to create/write: ");
        String fileName = scanner.nextLine();

        try { // Outer try: For opening the file (FileWriter)
            fileWriter = new FileWriter(fileName);
            System.out.println("File '" + fileName + "' opened successfully.");

            BufferedWriter bufferedWriter = null; // Declare inside outer try for inner finally
            try { // Inner try: For writing to the file (BufferedWriter)
                bufferedWriter = new BufferedWriter(fileWriter);
                System.out.print("Enter text to write to the file: ");
                String content = scanner.nextLine();

                if (content.contains("ERROR")) {
                    // Simulate an error during writing (e.g., disk full, permission denied)
                    throw new IOException("Simulated write error: Content contains 'ERROR'");
                }

                bufferedWriter.write(content);
                System.out.println("Content successfully written to file.");

            } catch (IOException e) { // Inner catch: Handles issues during writing
                System.err.println("Inner Catch (IOException): Error writing to file! " + e.getMessage());
            } finally { // Inner finally: Ensures BufferedWriter is closed
                if (bufferedWriter != null) {
                    try {
                        bufferedWriter.close();
                        System.out.println("BufferedWriter closed.");
                    } catch (IOException e) {
                        System.err.println("Error closing BufferedWriter: " + e.getMessage());
                    }
                }
            }

            System.out.println("Outer try block continued after inner operations.");

        } catch (IOException e) { // Outer catch: Handles issues during file opening
            System.err.println("Outer Catch (IOException): Error opening or general file operation! " + e.getMessage());
        } finally { // Outer finally: Ensures FileWriter is closed
            if (fileWriter != null) {
                try {
                    fileWriter.close();
                    System.out.println("FileWriter closed.");
                } catch (IOException e) {
                    System.err.println("Error closing FileWriter: " + e.getMessage());
                }
            }
            scanner.close();
            System.out.println("Scanner closed. Program finished.");
        }
    }
}
```

### Input and Output Examples:

**Scenario 1: Successful File Write**

*   **Input:**
    ```
    Enter filename to create/write: my_document.txt
    Enter text to write to the file: This is some sample text.
    ```
*   **Output:**
    ```
    Enter filename to create/write: my_document.txt
    File 'my_document.txt' opened successfully.
    Enter text to write to the file: This is some sample text.
    Content successfully written to file.
    BufferedWriter closed.
    Outer try block continued after inner operations.
    FileWriter closed.
    Scanner closed. Program finished.
    ```
    *(A file named `my_document.txt` will be created/overwritten in the same directory as the Java program, containing "This is some sample text.")*

**Scenario 2: Inner Write Error (Simulated)**

*   **Input:**
    ```
    Enter filename to create/write: error_file.txt
    Enter text to write to the file: This text will cause an ERROR.
    ```
*   **Output:**
    ```
    Enter filename to create/write: error_file.txt
    File 'error_file.txt' opened successfully.
    Enter text to write to the file: This text will cause an ERROR.
    Inner Catch (IOException): Error writing to file! Simulated write error: Content contains 'ERROR'
    BufferedWriter closed.
    Outer try block continued after inner operations.
    FileWriter closed.
    Scanner closed. Program finished.
    ```
    *Explanation:* The simulated `IOException` during `bufferedWriter.write()` is caught by the `inner catch`. The `inner finally` ensures the `BufferedWriter` is closed. The outer `try` continues, and its `finally` closes the `FileWriter`. The program exits gracefully.

**Scenario 3: Outer File Open Error (e.g., trying to write to a directory path)**

*   **Input:**
    ```
    Enter filename to create/write: /
    ```
*   **Output:**
    ```
    Enter filename to create/write: /
    Outer Catch (IOException): Error opening or general file operation! Is a directory
    FileWriter closed.
    Scanner closed. Program finished.
    ```
    *Explanation:* `FileWriter` cannot open a directory as a file. The `IOException` is thrown immediately when `new FileWriter(fileName)` is called, skipping the inner `try` block entirely. The `outer catch` handles it, and the `outer finally` attempts to close the `FileWriter` (which will be `null` in this specific case, but the `if` check handles it).

---

## Alternative/Best Practice: `try-with-resources`

For managing resources (like files, network connections, database connections), Java's `try-with-resources` statement (introduced in Java 7) is almost always a cleaner and safer alternative to deeply nested `try-finally` blocks. It automatically closes resources that implement `AutoCloseable` interface.

Here's how the File Operations example (`NestedTryFileExample`) would look using `try-with-resources`. Notice how much simpler it is, and you don't need manual `finally` blocks for closing.

```java
import java.io.FileWriter;
import java.io.IOException;
import java.io.BufferedWriter;
import java.util.Scanner;

public class TryWithResourcesAlternative {

    public static void main(String[] args) {
        Scanner scanner = new Scanner(System.in);
        System.out.print("Enter filename to create/write: ");
        String fileName = scanner.nextLine();

        // try-with-resources automatically closes fileWriter and bufferedWriter
        try (FileWriter fileWriter = new FileWriter(fileName);
             BufferedWriter bufferedWriter = new BufferedWriter(fileWriter)) {

            System.out.println("File '" + fileName + "' opened successfully.");
            System.out.print("Enter text to write to the file: ");
            String content = scanner.nextLine();

            if (content.contains("ERROR")) {
                throw new IOException("Simulated write error: Content contains 'ERROR'");
            }

            bufferedWriter.write(content);
            System.out.println("Content successfully written to file.");

        } catch (IOException e) { // A single catch block handles both opening and writing errors
            System.err.println("An I/O error occurred: " + e.getMessage());
        } finally {
            scanner.close();
            System.out.println("Scanner closed. Program finished.");
        }
    }
}
```

### Input and Output Examples (for TryWithResourcesAlternative):

The input/output behavior for the `try-with-resources` version will be very similar to the `NestedTryFileExample`, but the code is much more concise and less prone to resource leakage errors due to forgotten `close()` calls.

*   **Successful:**
    ```
    Enter filename to create/write: success.txt
    File 'success.txt' opened successfully.
    Enter text to write to the file: Hello World
    Content successfully written to file.
    Scanner closed. Program finished.
    ```
*   **Simulated Write Error:**
    ```
    Enter filename to create/write: write_fail.txt
    File 'write_fail.txt' opened successfully.
    Enter text to write to the file: This will cause an ERROR
    An I/O error occurred: Simulated write error: Content contains 'ERROR'
    Scanner closed. Program finished.
    ```
*   **File Open Error:**
    ```
    Enter filename to create/write: /
    An I/O error occurred: Is a directory
    Scanner closed. Program finished.
    ```

**Conclusion on `try-with-resources`:** While nested `try` blocks are valid and have their uses (especially for non-resource-related granular error handling), for resource management, `try-with-resources` is generally the superior and recommended approach as it simplifies code and improves reliability.