The `throw` keyword in Java is used to explicitly throw an instance of an exception. When a `throw` statement is executed, the current flow of execution is halted, and the exception object is propagated up the call stack, looking for a suitable `catch` block to handle it.

## `throw` Keyword in Java

### 1. Purpose

The primary purpose of the `throw` keyword is to:
*   **Signal an abnormal condition:** When a method encounters a situation it cannot handle or a condition that violates its contract, it can `throw` an exception to indicate that something went wrong.
*   **Create and propagate an exception:** It is used to create an instance of an exception class (e.g., `new IllegalArgumentException("message")`) and then immediately throw it.

### 2. Syntax

The basic syntax for the `throw` keyword is:

```java
throw new ExceptionType("Optional message");
```

*   `ExceptionType`: Must be a class that directly or indirectly extends `java.lang.Throwable`. Common examples include `RuntimeException`, `IllegalArgumentException`, `IOException`, `CustomException`, etc.
*   `"Optional message"`: A string message that describes the exception. This message can be retrieved later using the `getMessage()` method of the exception object.

### 3. Detailed Explanation

*   **Instance, Not Class:** You don't `throw` an exception class; you `throw` an *instance* (an object) of an exception class. That's why you often see `new` used with `throw`.
*   **Control Flow Disruption:** When `throw` is executed, the normal sequential execution of the program is immediately interrupted. The method where the exception was thrown will stop executing its remaining code.
*   **Call Stack Propagation:** The JVM then searches up the call stack for a `catch` block that can handle the type of exception thrown.
    *   If a suitable `catch` block is found, the execution jumps to that `catch` block.
    *   If no suitable `catch` block is found anywhere in the call stack, the program terminates, and the JVM prints a stack trace to the console.
*   **Checked vs. Unchecked Exceptions:**
    *   **Unchecked Exceptions (RuntimeException and its subclasses):** When you `throw` an unchecked exception, the compiler does *not* force you to either catch it or declare it in the method's `throws` clause. These usually represent programming errors (e.g., `NullPointerException`, `ArrayIndexOutOfBoundsException`, `IllegalArgumentException`).
    *   **Checked Exceptions (all other Exception subclasses, excluding `RuntimeException`):** When you `throw` a checked exception, the compiler *will* enforce that the method either:
        1.  **Handles it:** By enclosing the `throw` statement in a `try-catch` block.
        2.  **Declares it:** By adding a `throws` clause to the method signature, indicating that the method might throw this exception, thereby delegating the responsibility of handling to the caller.
*   **Relationship with `throws`:** It's crucial not to confuse `throw` with `throws`.
    *   `throw`: Used *inside* a method to *create and initiate* an exception.
    *   `throws`: Used in a method *signature* to *declare* that a method *might* throw one or more checked exceptions.

### 4. Examples

#### Example 1: Throwing an Unchecked Exception (`IllegalArgumentException`)

This example demonstrates throwing an `IllegalArgumentException` when a method receives an invalid argument. `IllegalArgumentException` is a subclass of `RuntimeException`, so it's an unchecked exception.

**Code:**

```java
public class UncheckedThrowExample {

    public static int divide(int numerator, int denominator) {
        if (denominator == 0) {
            // Throw an unchecked exception if the denominator is zero
            throw new IllegalArgumentException("Denominator cannot be zero.");
        }
        return numerator / denominator;
    }

    public static void main(String[] args) {
        System.out.println("--- Test Case 1: Valid Division ---");
        try {
            int result1 = divide(10, 2);
            System.out.println("Result of 10 / 2: " + result1);
        } catch (Exception e) {
            System.out.println("An unexpected error occurred: " + e.getMessage());
        }

        System.out.println("\n--- Test Case 2: Division by Zero ---");
        try {
            int result2 = divide(10, 0); // This will throw an exception
            System.out.println("Result of 10 / 0: " + result2); // This line will not be reached
        } catch (IllegalArgumentException e) {
            // Catching the specific unchecked exception
            System.out.println("Error: " + e.getMessage());
        } catch (Exception e) {
            // Catching any other unexpected exception
            System.out.println("An unexpected error occurred: " + e.getMessage());
        }

        System.out.println("\n--- Program continues ---");
    }
}
```

**Input (Implicit):**
The inputs are directly provided in the `main` method calls:
*   `divide(10, 2)`
*   `divide(10, 0)`

**Output:**

```
--- Test Case 1: Valid Division ---
Result of 10 / 2: 5

--- Test Case 2: Division by Zero ---
Error: Denominator cannot be zero.

--- Program continues ---
```

**Explanation:**
*   In Test Case 1, `divide(10, 2)` executes normally, and the result is printed.
*   In Test Case 2, `divide(10, 0)` calls the `divide` method. Inside `divide`, the `if (denominator == 0)` condition is true, so `throw new IllegalArgumentException("Denominator cannot be zero.");` is executed.
*   The `throw` statement immediately halts `divide` method execution. The `main` method's `try` block catches this `IllegalArgumentException`, and the message "Error: Denominator cannot be zero." is printed. The program then continues execution after the `try-catch` block.

#### Example 2: Throwing a Checked Exception (`IOException`)

This example simulates a file operation that might fail. `IOException` is a checked exception, so the compiler forces us to either catch it or declare it in the method signature.

**Code:**

```java
import java.io.IOException;

public class CheckedThrowExample {

    // This method declares that it might throw an IOException
    public static void processFile(String fileName) throws IOException {
        System.out.println("Attempting to process file: " + fileName);

        if (!fileName.endsWith(".txt")) {
            // Throw a checked exception if the file name is not a .txt file
            // Since IOException is checked, we must declare 'throws IOException' in method signature
            throw new IOException("Only .txt files are supported for processing.");
        }

        // Simulate file processing logic here
        System.out.println("File '" + fileName + "' processed successfully.");
    }

    public static void main(String[] args) {
        System.out.println("--- Test Case 1: Valid File ---");
        try {
            processFile("document.txt");
        } catch (IOException e) {
            System.out.println("Caught an error processing file: " + e.getMessage());
        }

        System.out.println("\n--- Test Case 2: Invalid File Type ---");
        try {
            processFile("image.jpg"); // This will throw an IOException
        } catch (IOException e) {
            // We must catch the IOException here, as declared by processFile method
            System.out.println("Caught an error processing file: " + e.getMessage());
        }

        System.out.println("\n--- Program continues ---");
    }
}
```

**Input (Implicit):**
The inputs are directly provided in the `main` method calls:
*   `processFile("document.txt")`
*   `processFile("image.jpg")`

**Output:**

```
--- Test Case 1: Valid File ---
Attempting to process file: document.txt
File 'document.txt' processed successfully.

--- Test Case 2: Invalid File Type ---
Attempting to process file: image.jpg
Caught an error processing file: Only .txt files are supported for processing.

--- Program continues ---
```

**Explanation:**
*   The `processFile` method signature includes `throws IOException`, indicating to the compiler and callers that this method might throw an `IOException`.
*   In Test Case 1, `processFile("document.txt")` proceeds normally because the condition `!fileName.endsWith(".txt")` is false.
*   In Test Case 2, `processFile("image.jpg")` triggers the `throw new IOException(...)` statement.
*   Because `IOException` is a checked exception, the `main` method is forced to enclose the call to `processFile` within a `try-catch` block to handle it. The `catch` block then prints the error message.

#### Example 3: Throwing a Custom Exception

It's common practice to create your own exception classes for application-specific error conditions. This example defines a `TooYoungException` and `TooOldException`.

**Code:**

```java
// 1. Define Custom Exception Class 1
class TooYoungException extends Exception {
    public TooYoungException(String message) {
        super(message);
    }
}

// 2. Define Custom Exception Class 2
class TooOldException extends Exception {
    public TooOldException(String message) {
        super(message);
    }
}

public class CustomThrowExample {

    public static void validateAge(int age) throws TooYoungException, TooOldException {
        if (age < 18) {
            throw new TooYoungException("You are too young to apply.");
        } else if (age > 60) {
            throw new TooOldException("You are too old to apply.");
        } else {
            System.out.println("Age " + age + " is valid for application.");
        }
    }

    public static void main(String[] args) {
        System.out.println("--- Test Case 1: Valid Age ---");
        try {
            validateAge(30);
        } catch (TooYoungException | TooOldException e) {
            System.out.println("Error validating age: " + e.getMessage());
        }

        System.out.println("\n--- Test Case 2: Too Young ---");
        try {
            validateAge(15); // Will throw TooYoungException
        } catch (TooYoungException e) {
            System.out.println("Caught specific error: " + e.getMessage());
        } catch (TooOldException e) {
            System.out.println("Caught specific error: " + e.getMessage());
        }

        System.out.println("\n--- Test Case 3: Too Old ---");
        try {
            validateAge(65); // Will throw TooOldException
        } catch (TooYoungException e) {
            System.out.println("Caught specific error: " + e.getMessage());
        } catch (TooOldException e) {
            System.out.println("Caught specific error: " + e.getMessage());
        }

        System.out.println("\n--- Program continues ---");
    }
}
```

**Input (Implicit):**
The inputs are directly provided in the `main` method calls:
*   `validateAge(30)`
*   `validateAge(15)`
*   `validateAge(65)`

**Output:**

```
--- Test Case 1: Valid Age ---
Age 30 is valid for application.

--- Test Case 2: Too Young ---
Caught specific error: You are too young to apply.

--- Test Case 3: Too Old ---
Caught specific error: You are too old to apply.

--- Program continues ---
```

**Explanation:**
*   We define two custom checked exception classes: `TooYoungException` and `TooOldException`, both extending `Exception`.
*   The `validateAge` method declares that it can `throw` either of these custom exceptions.
*   In the `main` method, we use `try-catch` blocks to call `validateAge`.
*   When an age is too young (e.g., 15), `throw new TooYoungException(...)` is executed, and the corresponding `catch (TooYoungException e)` block handles it.
*   Similarly, when an age is too old (e.g., 65), `throw new TooOldException(...)` is executed, and the `catch (TooOldException e)` block handles it.
*   This demonstrates how `throw` is used with custom exceptions for more precise error handling tailored to your application's logic.

By understanding and correctly using the `throw` keyword, you can create robust and maintainable Java applications that gracefully handle unexpected situations.